Workbook

Sheet Sheet1
A1: SOFT24H
A2: BẢNG LIỆT KÊ CHỨC NĂNG
A3: PHẦN MỀM CASHIER TRÊN ANDROID
A5: STT | B5: Chức năng | C5: Mô tả | D5: Ghi chú
A7: A | B7: Yêu cầu chung | C7: Hiển thị trên nhiều kích thước màn hình, phù hợp với cả máy tính bảng và điện thoại
C8: Kích thước ưu tiền là màn 7inch độ phân giải 1024 x 600
C9: Hoạt động tốt trên cả lan và 3g
C10: Phù hợp với việc không ổn định của kết nối không dây
C11: Có khả năng tự cập nhật phiên bản mới (trong config có biến autoupdate)
A13: B | B13: Chi tiết
A14: I | B14: Kết nối CSDL | C14: - User / Pass: Đặt ngầm trong code hoặc file có mã hóa
C15: - IP, tên CSDL, Port: Dùng file config
A17: II | B17: Login
A18: 1 | B18: Giao diện | C18: Sử dụng tông màu giống phần mềm
A19: 2 | B19: Chức năng | C19: Kiểm tra tính hợp lệ của user/pass | D19: Function của CSDL sẽ trả về thông tin phân quyền
C20: Tắt/mở chức năng chương trình theo phân quyền
C21: Ghi nhận thông tin ca làm việc | D21: Ghi vào bảng Đóng ca
C22: Thông báo các chương trình khuyến mãi, giảm giá hiện hành | D22: Phần này làm sau
C23: Hiển thị các note của quản lý (danh sách các món cần đẩy mạnh, món bị hết, ….. | D23: Phần này làm sau
A25: III | B25: Sơ đồ bàn
A26: 1 | B26: Giao diện | C26: Hiển thị theo dạng ô bàn cờ
C27: Chia làm 2 tab (bàn trống, bàn đang sử dụng)
C28: * Bàn trống
C29: - Danh sách bàn (nếu có dữ liệu trong dmban)
C30: + Chia tab theo khu vực | D30: Theo DMkhuvuc
C31: + Chức năng Thêm bàn | D31: Khi người dùng Click vào bào bàn thì thực hiện chức năng tạo bàn mới
C32: - Tạo bàn: dùng ô text để nhập số bàn và thực hiện chức năng tạo bàn mới
C33: * Bàn đang sử dụng
C34: + Chia tab theo cashier | D34: Select trong bkxuatban lấy số bàn và cs
C35: + Hiển thị mầu theo trạng thái (đã in bill và chưa in bill) | D35: Trạng thái 1: đã in bill, 2: chưa in bill (trong bkxuatban)
A36: 2 | B36: Chức năng
A37: a | B37: Tạo bàn mới | C37: Tạo 1 bàn trong bkxuatban
A38: b | B38: Xem bàn đang sử dụng | C38: Khi người dùng chọn 1 bàn đang sử dụng thì hiển thị các chức năng liên quan | D38: Hiển thị thông tin bàn đang xem: Doanh thu, giảm giá, thanh toán ..
C39: - Xem chi tiết bill
C40: - Thêm món mới trong menu
C41: - Thêm món mới ngoài danh mục
C42: - Trừ món
C43: - Giảm giá
C44: - Tính thêm phí | D44: Trao đổi thêm
C45: - In Order
...

Sheet Comment

Sheet Sheet2

Sheet Sheet4
B2: 1 | C2: 1400003006-997 | D2: 320081024 | E2: 1400003006 | F2: 997 | G2: 3 | H2: 446250 | I2: 1785000 | J2: 1 | K2: 7 | O2: Quan kaki nam 123 TH595 | P2: ChiÕc | R2: HN004 | S2: 42219.665
B3: 1 | C3: 1400003006-5399 | D3: 320081020 | E3: 1400003006 | F3: 5399 | G3: 2 | H3: 167500 | I3: 670000 | J3: 1 | K3: 7 | O3: QuÇn ©u nam ATN1159 335 | P3: ChiÕc | R3: HN004 | S3: 42219.665
B4: 1 | C4: 1400003006-7298 | D4: 320081018 | E4: 1400003006 | F4: 7298 | G4: 1 | H4: 105000 | I4: 420000 | J4: 1 | K4: 7 | O4: Ao somi Owen 420 | P4: ChiÕc | R4: HN004 | S4: 42219.665
B5: 1 | C5: 1400003006-7358 | D5: 320081008 | E5: 1400003006 | F5: 7358 | G5: 2 | H5: 210000 | I5: 840000 | J5: 1 | K5: 7 | O5: Ao so mi owen 420 | P5: ChiÕc | R5: HN004 | S5: 42219.665
B6: 1 | C6: 1400003006-7422 | D6: 320081016 | E6: 1400003006 | F6: 7422 | G6: 1 | H6: 96500 | I6: 386000 | J6: 1 | K6: 7 | O6: SMOW DT 386 | P6: ChiÕc | R6: HN004 | S6: 42219.665
B7: 1 | C7: 1400003006-8015 | D7: 320081030 | E7: 1400003006 | F7: 8015 | G7: 1 | H7: 147500 | I7: 590000 | J7: 1 | K7: 7 | O7: QUAN KAKI 590 | P7: ChiÕc | R7: HN004 | S7: 42219.665
B8: 1 | C8: 1400003006-8077 | D8: 320081029 | E8: 1400003006 | F8: 8077 | G8: 1 | H8: 120000 | I8: 480000 | J8: 1 | K8: 7 | O8: QUAN AU OW480 | P8: ChiÕc | R8: HN004 | S8: 42219.665
B9: 1 | C9: 1400003006-11862 | D9: 320080995 | E9: 1400003006 | F9: 11862 | G9: 2 | H9: 173800 | I9: 790000 | J9: 1 | K9: 7 | O9: SMDT n?n tr?ng s?c ghi 395 | P9: ChiÕc | R9: HN004 | S9: 42219.665
B10: 1 | C10: 1400003006-11883 | D10: 320080993 | E10: 1400003006 | F10: 11883 | G10: 3 | H10: 310200 | I10: 1410000 | J10: 1 | K10: 7 | O10: Ao so mi nam dai tay VT470 | P10: ChiÕc | R10: HN004 | S10: 42219.665
B11: 1 | C11: 1400003006-11973 | D11: 320080991 | E11: 1400003006 | F11: 11973 | G11: 1 | H11: 86900 | I11: 395000 | J11: 1 | K11: 7 | O11: Ao so mi CT VT395 | P11: ChiÕc | R11: HN004 | S11: 42219.665
B12: 1 | C12: 1400003006-12583 | D12: 320080998 | E12: 1400003006 | F12: 12583 | G12: 1 | H12: 63360 | I12: 288000 | J12: 1 | K12: 7 | O12: smdt caro xanh nâu VL 288 | P12: ChiÕc | R12: HN004 | S12: 42219.665
B13: 1 | C13: 1400003006-12652 | D13: 320081001 | E13: 1400003006 | F13: 12652 | G13: 1 | H13: 102300 | I13: 465000 | J13: 1 | K13: 7 | O13: S¬ mi nam VT-465 | P13: ChiÕc | R13: HN004 | S13: 42219.665
... B582: 1 | C582: 3100000004-13643 | D582: 468 | E582: 3100000004 | F582: 13643 | G582: 10 | H582: 0 | I582: 610000 | J582: 1 | K582: 7 | O582: Vay lanh nhi THN87 | P582: ChiÕc | R582: HN010 | S582: 42119.568
A585: 1400003006 | B585: =SUMIF($E$2:$E$582,C585,$I$2:$I$582)-H585 -> 0 | C585: 1400003006 | D585: 42219 | E585: CS1-003006 | F585: 140165 | G585: 2 | H585: 20857000 | I585: 4988680 | L585: 0 | M585: 0 | N585: 0.60902778 | O585: BB | P585: 1 | Q585: 201508031 | R585: 3 | S585: CS1 | U585: 1 | V585: 0.62708333 | X585: 0 | Y585: HN004 | Z585: THANHHOA | AA585: 42219.665
A586: 1400003017 | B586: =SUMIF($E$2:$E$582,C586,$I$2:$I$582)-H586 -> 0 | C586: 1400003017 | D586: 42219 | E586: CS1-003017 | F586: 311461 | G586: 2 | H586: 20813000 | I586: 5002520 | L586: 0 | M586: 0 | N586: 0.63402778 | O586: BB | P586: 1 | Q586: 201508031 | R586: 3 | S586: CS1 | U586: 1 | V586: 0.64375 | X586: 0 | Y586: HN004 | Z586: THANHHOA | AA586: 42219.665
A587: 1400003094 | B587: =SUMIF($E$2:$E$582,C587,$I$2:$I$582)-H587 -> 0 | C587: 1400003094 | D587: 42222 | E587: CS1-003094 | F587: 143197 | G587: 2 | H587: 33735000 | I587: 9021630 | L587: 0 | M587: 0 | N587: 0.40138889 | O587: BB | P587: 1 | Q587: 201508061 | R587: 3 | S587: CS1 | U587: 1 | V587: 0.40902778 | X587: 0 | Y587: HN004 | Z587: THANHHOA | AA587: 42222.426
A588: 1400003095 | B588: =SUMIF($E$2:$E$582,C588,$I$2:$I$582)-H588 -> 0 | C588: 1400003095 | D588: 42222 | E588: CS1-003095 | F588: 140331 | G588: 2 | H588: 14220000 | I588: 3326400 | L588: 0 | M588: 0 | N588: 0.40902778 | O588: BB | P588: 1 | Q588: 201508061 | R588: 3 | S588: CS1 | U588: 1 | V588: 0.41111111 | X588: 0 | Y588: HN004 | Z588: THANHHOA | AA588: 42222.426
A589: 1400003096 | B589: =SUMIF($E$2:$E$582,C589,$I$2:$I$582)-H589 -> 0 | C589: 1400003096 | D589: 42222 | E589: CS1-003096 | F589: 2 | G589: 2 | H589: -3720000 | I589: 0 | L589: 0 | M589: 0 | N589: 0.41458333 | O589: BB | P589: 1 | Q589: 201508061 | R589: 3 | S589: CS1 | U589: 1 | V589: 0.41527778 | X589: 0 | Y589: HN004 | Z589: THANHHOA | AA589: 42222.426
A590: 1400003097 | B590: =SUMIF($E$2:$E$582,C590,$I$2:$I$582)-H590 -> 0 | C590: 1400003097 | D590: 42222 | E590: CS1-003097 | F590: 140632 | G590: 2 | H590: 9442000 | I590: 2079170 | L590: 0 | M590: 0 | N590: 0.41805556 | O590: BB | P590: 1 | Q590: 201508061 | R590: 3 | S590: CS1 | U590: 1 | V590: 0.42152778 | X590: 0 | Y590: HN004 | Z590: THANHHOA | AA590: 42222.426
A591: 1400003098 | B591: =SUMIF($E$2:$E$582,C591,$I$2:$I$582)-H591 -> 0 | C591: 1400003098 | D591: 42222 | E591: CS1-003098 | F591: 140401 | G591: 2 | H591: 1081000 | I591: 252670 | L591: 0 | M591: 0 | N591: 0.41944444 | O591: BB | P591: 1 | Q591: 201508061 | R591: 3 | S591: CS1 | U591: 1 | V591: 0.41944444 | X591: 0 | Y591: HN004 | Z591: THANHHOA | AA591: 42222.426
A592: 1400003103 | B592: =SUMIF($E$2:$E$582,C592,$I$2:$I$582)-H592 -> 0 | C592: 1400003103 | D592: 42222 | E592: CS1-003103 | F592: 140268 | G592: 2 | H592: 4186000 | I592: 920920 | L592: 0 | M592: 0 | N592: 0.43263889 | O592: BB | P592: 1 | Q592: 201508061 | R592: 3 | S592: CS1 | U592: 1 | V592: 0.43472222 | X592: 0 | Y592: HN004 | Z592: THANHHOA | AA592: 42222.435
A593: 1400003104 | B593: =SUMIF($E$2:$E$582,C593,$I$2:$I$582)-H593 -> 0 | C593: 1400003104 | D593: 42222 | E593: CS1-003104 | F593: 141539 | G593: 2 | H593: 15084000 | I593: 3587160 | L593: 0 | M593: 0 | N593: 0.43611111 | O593: BB | P593: 1 | Q593: 201508061 | R593: 3 | S593: CS1 | U593: 1 | V593: 0.44097222 | X593: 0 | Y593: HN004 | Z593: THANHHOA | AA593: 42222.442
A594: 1400003110 | B594: =SUMIF($E$2:$E$582,C594,$I$2:$I$582)-H594 -> 0 | C594: 1400003110 | D594: 42222 | E594: CS1-003110 | F594: 2 | G594: 2 | H594: 4560000 | I594: 0 | L594: 0 | M594: 0 | N594: 0.46388889 | O594: BB | P594: 1 | Q594: 201508061 | R594: 3 | S594: CS1 | U594: 1 | V594: 0.46527778 | X594: 0 | Y594: HN004 | Z594: THANHHOA | AA594: 42222.466
A595: 1400003111 | B595: =SUMIF($E$2:$E$582,C595,$I$2:$I$582)-H595 -> 0 | C595: 1400003111 | D595: 42222 | E595: CS1-003111 | F595: 140148 | G595: 2 | H595: 6119000 | I595: 1346180 | L595: 0 | M595: 0 | N595: 0.46527778 | O595: BB | P595: 1 | Q595: 201508061 | R595: 3 | S595: CS1 | U595: 1 | V595: 0.475 | X595: 0 | Y595: HN004 | Z595: THANHHOA | AA595: 42222.475
A596: 1400003112 | B596: =SUMIF($E$2:$E$582,C596,$I$2:$I$582)-H596 -> 0 | C596: 1400003112 | D596: 42222 | E596: CS1-003112 | F596: 140393 | G596: 2 | H596: 25364000 | I596: 5798370 | L596: 0 | M596: 0 | N596: 0.46527778 | O596: BB | P596: 1 | Q596: 201508061 | R596: 3 | S596: CS1 | U596: 1 | V596: 0.48333333 | X596: 0 | Y596: HN004 | Z596: THANHHOA | AA596: 42222.484
... A786: 3100000004 | B786: =SUMIF($E$2:$E$582,C786,$I$2:$I$582)-H786 -> 3823000 | C786: 3100000004 | D786: 42119 | E786: CS1-000004 | F786: 2 | G786: 2 | H786: -1265000 | I786: 0 | L786: 0 | M786: 0 | N786: 0.39375 | O786: BL | P786: 1 | Q786: 201504251 | R786: 3 | S786: CS1 | U786: 1 | V786: 0.7 | X786: 0 | Y786: HN010 | Z786: THUNGAN | AA786: 42119.7

Sheet Sheet5
D3: 320081025 | E3: 1
D4: 320081021 | E4: 2
D5: 320081019 | E5: 3
D6: 320081009 | E6: 4
D7: 320081017 | E7: 5
D8: 320081031 | E8: 6
D9: 320081028 | E9: 7
D10: 320080994 | E10: 8
D11: 320080992 | E11: 9
D12: 320080990 | E12: 10
D13: 320080999 | E13: 11
D14: 320081000 | E14: 12
... D546: 320083099 | E546: 544

Sheet Sheet3
A1: 1 | B1: 1
A3: =IF(VLOOKUP(E3,Sheet4!$A$585:$B$786,2,0)=0,1, ) -> 1 | B3: =IF(COUNTIF($C$2:$C3,C3)=1,1, ) -> 1 | C3: =E3&"-"&F3 -> 1400003006-997 | D3: 320081024 | E3: 1400003006 | F3: 997 | G3: 3 | H3: 446250 | I3: 1785000 | J3: 1 | K3: 7 | O3: Quan kaki nam 123 TH595 | P3: ChiÕc | R3: HN004 | S3: 42219.665
A4: =IF(VLOOKUP(E4,Sheet4!$A$585:$B$786,2,0)=0,1, ) -> 1 | B4: =IF(COUNTIF($C$2:$C4,C4)=1,1, ) | C4: =E4&"-"&F4 -> 1400003006-997 | D4: 320081025 | E4: 1400003006 | F4: 997 | G4: 3 | H4: 446250 | I4: 1785000 | J4: 1 | K4: 7 | O4: Quan kaki nam 123 TH595 | P4: ChiÕc | R4: HN004 | S4: 42219.665
A5: =IF(VLOOKUP(E5,Sheet4!$A$585:$B$786,2,0)=0,1, ) -> 1 | B5: =IF(COUNTIF($C$2:$C5,C5)=1,1, ) -> 1 | C5: =E5&"-"&F5 -> 1400003006-5399 | D5: 320081020 | E5: 1400003006 | F5: 5399 | G5: 2 | H5: 167500 | I5: 670000 | J5: 1 | K5: 7 | O5: QuÇn ©u nam ATN1159 335 | P5: ChiÕc | R5: HN004 | S5: 42219.665
A6: =IF(VLOOKUP(E6,Sheet4!$A$585:$B$786,2,0)=0,1, ) -> 1 | B6: =IF(COUNTIF($C$2:$C6,C6)=1,1, ) | C6: =E6&"-"&F6 -> 1400003006-5399 | D6: 320081021 | E6: 1400003006 | F6: 5399 | G6: 2 | H6: 167500 | I6: 670000 | J6: 1 | K6: 7 | O6: QuÇn ©u nam ATN1159 335 | P6: ChiÕc | R6: HN004 | S6: 42219.665
A7: =IF(VLOOKUP(E7,Sheet4!$A$585:$B$786,2,0)=0,1, ) -> 1 | B7: =IF(COUNTIF($C$2:$C7,C7)=1,1, ) -> 1 | C7: =E7&"-"&F7 -> 1400003006-7298 | D7: 320081018 | E7: 1400003006 | F7: 7298 | G7: 1 | H7: 105000 | I7: 420000 | J7: 1 | K7: 7 | O7: Ao somi Owen 420 | P7: ChiÕc | R7: HN004 | S7: 42219.665
A8: =IF(VLOOKUP(E8,Sheet4!$A$585:$B$786,2,0)=0,1, ) -> 1 | B8: =IF(COUNTIF($C$2:$C8,C8)=1,1, ) | C8: =E8&"-"&F8 -> 1400003006-7298 | D8: 320081019 | E8: 1400003006 | F8: 7298 | G8: 1 | H8: 105000 | I8: 420000 | J8: 1 | K8: 7 | O8: Ao somi Owen 420 | P8: ChiÕc | R8: HN004 | S8: 42219.665
A9: =IF(VLOOKUP(E9,Sheet4!$A$585:$B$786,2,0)=0,1, ) -> 1 | B9: =IF(COUNTIF($C$2:$C9,C9)=1,1, ) -> 1 | C9: =E9&"-"&F9 -> 1400003006-7358 | D9: 320081008 | E9: 1400003006 | F9: 7358 | G9: 2 | H9: 210000 | I9: 840000 | J9: 1 | K9: 7 | O9: Ao so mi owen 420 | P9: ChiÕc | R9: HN004 | S9: 42219.665
A10: =IF(VLOOKUP(E10,Sheet4!$A$585:$B$786,2,0)=0,1, ) -> 1 | B10: =IF(COUNTIF($C$2:$C10,C10)=1,1, ) | C10: =E10&"-"&F10 -> 1400003006-7358 | D10: 320081009 | E10: 1400003006 | F10: 7358 | G10: 2 | H10: 210000 | I10: 840000 | J10: 1 | K10: 7 | O10: Ao so mi owen 420 | P10: ChiÕc | R10: HN004 | S10: 42219.665
A11: =IF(VLOOKUP(E11,Sheet4!$A$585:$B$786,2,0)=0,1, ) -> 1 | B11: =IF(COUNTIF($C$2:$C11,C11)=1,1, ) -> 1 | C11: =E11&"-"&F11 -> 1400003006-7422 | D11: 320081016 | E11: 1400003006 | F11: 7422 | G11: 1 | H11: 96500 | I11: 386000 | J11: 1 | K11: 7 | O11: SMOW DT 386 | P11: ChiÕc | R11: HN004 | S11: 42219.665
A12: =IF(VLOOKUP(E12,Sheet4!$A$585:$B$786,2,0)=0,1, ) -> 1 | B12: =IF(COUNTIF($C$2:$C12,C12)=1,1, ) | C12: =E12&"-"&F12 -> 1400003006-7422 | D12: 320081017 | E12: 1400003006 | F12: 7422 | G12: 1 | H12: 96500 | I12: 386000 | J12: 1 | K12: 7 | O12: SMOW DT 386 | P12: ChiÕc | R12: HN004 | S12: 42219.665
A13: =IF(VLOOKUP(E13,Sheet4!$A$585:$B$786,2,0)=0,1, ) -> 1 | B13: =IF(COUNTIF($C$2:$C13,C13)=1,1, ) -> 1 | C13: =E13&"-"&F13 -> 1400003006-8015 | D13: 320081030 | E13: 1400003006 | F13: 8015 | G13: 1 | H13: 147500 | I13: 590000 | J13: 1 | K13: 7 | O13: QUAN KAKI 590 | P13: ChiÕc | R13: HN004 | S13: 42219.665
A14: =IF(VLOOKUP(E14,Sheet4!$A$585:$B$786,2,0)=0,1, ) -> 1 | B14: =IF(COUNTIF($C$2:$C14,C14)=1,1, ) | C14: =E14&"-"&F14 -> 1400003006-8015 | D14: 320081031 | E14: 1400003006 | F14: 8015 | G14: 1 | H14: 147500 | I14: 590000 | J14: 1 | K14: 7 | O14: QUAN KAKI 590 | P14: ChiÕc | R14: HN004 | S14: 42219.665
... A1127: =IF(VLOOKUP(E1127,Sheet4!$A$585:$B$786,2,0)=0,1, ) | B1127: =IF(COUNTIF($C$2:$C1127,C1127)=1,1, ) -> 1 | C1127: =E1127&"-"&F1127 -> 3100000004-13643 | D1127: 468 | E1127: 3100000004 | F1127: 13643 | G1127: 10 | H1127: 0 | I1127: 610000 | J1127: 1 | K1127: 7 | O1127: Vay lanh nhi THN87 | P1127: ChiÕc | R1127: HN010 | S1127: 42119.568
